Workbook
Name Slicer_Area_code: #N/A
Name Slicer_Churn: #N/A
Name Slicer_International_plan: #N/A
Name Slicer_State: #N/A
Name Slicer_Voice_mail_plan: #N/A

Sheet churn-bigml-20
A1: State | B1: Account length | C1: Area code | D1: International plan | E1: Voice mail plan | F1: Number vmail messages | G1: Total day minutes | H1: Total day calls | I1: Total day charge | J1: Total eve minutes | K1: Total eve calls | L1: Total eve charge | M1: Total night minutes | N1: Total night calls | O1: Total night charge | P1: Total intl minutes | Q1: Total intl calls | R1: Total intl charge | S1: Customer service calls | T1: Churn | U1: Total usage(Min) | V1: Total charges | W1: Total calls | X1: Customer service risk level | Y1: Customer usage risk level | Z1: Charges risk level | AA1: Intl usage behaviour | AB1: Voicemail usage behaviour | AC1: Risk segmentation
A2: LA | B2: 117 | C2: 408 | D2: No | E2: No | F2: 0 | G2: 184.5 | H2: 97 | I2: 31.37 | J2: 351.6 | K2: 80 | L2: 29.89 | M2: 215.8 | N2: 90 | O2: 9.71 | P2: 8.7 | Q2: 4 | R2: 2.35 | S2: 1 | T2: FALSE | U2: =IFERROR(SUM(Table1[[#This Row],[Total day minutes]],Table1[[#This Row],[Total eve minutes]],Table1[[#This Row],[Total night minutes]],Table1[[#This Row],[Total intl minutes]]),0) -> 760.6 | V2: =SUM(Table1[[#This Row],[Total intl charge]],Table1[[#This Row],[Total night charge]],Table1[[#This Row],[Total eve charge]],Table1[[#This Row],[Total day charge]]) -> 73.32 | W2: =SUM(Table1[[#This Row],[Total intl calls]],Table1[[#This Row],[Total night calls]],Table1[[#This Row],[Total eve calls]],Table1[[#This Row],[Total day calls]]) -> 271 | X2: {=_xlfn.IFS(Table1[[#This Row],[Customer service calls]]>=4,"High risk",Table1[[#This Row],[Customer service calls]]>=2,"Medium risk",TRUE,"Low risk")} -> Low risk | Y2: {=IFERROR(_xlfn.IFS(Table1[[#This Row],[Total usage(Min)]]>=AVERAGE(U:U)*1.1,"High risk",Table1[[#This Row],[Total usage(Min)]]<= AVERAGE(U:U)*0.9,"Low risk",TRUE,"Medium risk"),"N/A")} -> High risk | Z2: {=IFERROR(_xlfn.IFS(Table1[[#This Row],[Total charges]]>=AVERAGE(V:V)*1.1,"High risk",Table1[[#This Row],[Total charges]]<=AVERAGE(V:V)*0.9,"Low risk",TRUE,"Medium risk"),"N/A")} -> High risk | AA2: =IF(AND(Table1[[#This Row],[International plan]]="Yes",Table1[[#This Row],[Total intl minutes]]>0),"Paying & Using",IF(AND(Table1[[#This Row],[International plan]]="Yes",Table1[[#This Row],[Total intl minutes]]=0),"Paying but not using",IF(AND(Table1[[#This Row],[International plan]]="No",Table1[[#This Row],[Total intl minutes]]>0),"Unplanned usage","Inactive"))) -> Unplanned usage | AB2: =IF(AND(Table1[[#This Row],[Voice mail plan]]="Yes",Table1[[#This Row],[Number vmail messages]]>0),"Active user",IF(AND(Table1[[#This Row],[Voice mail plan]]="Yes",Table1[[#This Row],[Number vmail messages]]=0),"Unused",IF(AND(Table1[[#This Row],[Voice mail plan]]="No",Table1[[#This Row],[Number vmail messages]]>0),"Unsubscribed usage","Inactive"))) -> Inactive | AC2: {=_xlfn.IFS( AND(Table1[[#This Row],[Customer service risk level]]="High risk", Table1[[#This Row],[Intl usage behaviour]]="Unplanned Usage"),"High Risk", OR(Table1[[#This Row],[Customer service risk level]]="Medium risk", Table1[[#This Row],[Charges risk level]]="High risk "),"Medium Risk", TRUE,"Low Risk" )} -> Low Risk
A3: IN | B3: 65 | C3: 415 | D3: No | E3: No | F3: 0 | G3: 129.1 | H3: 137 | I3: 21.95 | J3: 228.5 | K3: 83 | L3: 19.42 | M3: 208.8 | N3: 111 | O3: 9.4 | P3: 12.7 | Q3: 6 | R3: 3.43 | S3: 4 | T3: TRUE | U3: =IFERROR(SUM(Table1[[#This Row],[Total day minutes]],Table1[[#This Row],[Total eve minutes]],Table1[[#This Row],[Total night minutes]],Table1[[#This Row],[Total intl minutes]]),0) -> 579.1 | V3: =SUM(Table1[[#This Row],[Total intl charge]],Table1[[#This Row],[Total night charge]],Table1[[#This Row],[Total eve charge]],Table1[[#This Row],[Total day charge]]) -> 54.2 | W3: =SUM(Table1[[#This Row],[Total intl calls]],Table1[[#This Row],[Total night calls]],Table1[[#This Row],[Total eve calls]],Table1[[#This Row],[Total day calls]]) -> 337 | X3: {=_xlfn.IFS(Table1[[#This Row],[Customer service calls]]>=4,"High risk",Table1[[#This Row],[Customer service calls]]>=2,"Medium risk",TRUE,"Low risk")} -> High risk | Y3: {=IFERROR(_xlfn.IFS(Table1[[#This Row],[Total usage(Min)]]>=AVERAGE(U:U)*1.1,"High risk",Table1[[#This Row],[Total usage(Min)]]<= AVERAGE(U:U)*0.9,"Low risk",TRUE,"Medium risk"),"N/A")} -> Medium risk | Z3: {=IFERROR(_xlfn.IFS(Table1[[#This Row],[Total charges]]>=AVERAGE(V:V)*1.1,"High risk",Table1[[#This Row],[Total charges]]<=AVERAGE(V:V)*0.9,"Low risk",TRUE,"Medium risk"),"N/A")} -> Medium risk | AA3: =IF(AND(Table1[[#This Row],[International plan]]="Yes",Table1[[#This Row],[Total intl minutes]]>0),"Paying & Using",IF(AND(Table1[[#This Row],[International plan]]="Yes",Table1[[#This Row],[Total intl minutes]]=0),"Paying but not using",IF(AND(Table1[[#This Row],[International plan]]="No",Table1[[#This Row],[Total intl minutes]]>0),"Unplanned usage","Inactive"))) -> Unplanned usage | AB3: =IF(AND(Table1[[#This Row],[Voice mail plan]]="Yes",Table1[[#This Row],[Number vmail messages]]>0),"Active user",IF(AND(Table1[[#This Row],[Voice mail plan]]="Yes",Table1[[#This Row],[Number vmail messages]]=0),"Unused",IF(AND(Table1[[#This Row],[Voice mail plan]]="No",Table1[[#This Row],[Number vmail messages]]>0),"Unsubscribed usage","Inactive"))) -> Inactive | AC3: {=_xlfn.IFS( AND(Table1[[#This Row],[Customer service risk level]]="High risk", Table1[[#This Row],[Intl usage behaviour]]="Unplanned Usage"),"High Risk", OR(Table1[[#This Row],[Customer service risk level]]="Medium risk", Table1[[#This Row],[Charges risk level]]="High risk "),"Medium Risk", TRUE,"Low Risk" )} -> High Risk
A4: NY | B4: 161 | C4: 415 | D4: No | E4: No | F4: 0 | G4: 332.9 | H4: 67 | I4: 56.59 | J4: 317.8 | K4: 97 | L4: 27.01 | M4: 160.6 | N4: 128 | O4: 7.23 | P4: 5.4 | Q4: 9 | R4: 1.46 | S4: 4 | T4: TRUE | U4: =IFERROR(SUM(Table1[[#This Row],[Total day minutes]],Table1[[#This Row],[Total eve minutes]],Table1[[#This Row],[Total night minutes]],Table1[[#This Row],[Total intl minutes]]),0) -> 816.7 | V4: =SUM(Table1[[#This Row],[Total intl charge]],Table1[[#This Row],[Total night charge]],Table1[[#This Row],[Total eve charge]],Table1[[#This Row],[Total day charge]]) -> 92.29 | W4: =SUM(Table1[[#This Row],[Total intl calls]],Table1[[#This Row],[Total night calls]],Table1[[#This Row],[Total eve calls]],Table1[[#This Row],[Total day calls]]) -> 301 | X4: {=_xlfn.IFS(Table1[[#This Row],[Customer service calls]]>=4,"High risk",Table1[[#This Row],[Customer service calls]]>=2,"Medium risk",TRUE,"Low risk")} -> High risk | Y4: {=IFERROR(_xlfn.IFS(Table1[[#This Row],[Total usage(Min)]]>=AVERAGE(U:U)*1.1,"High risk",Table1[[#This Row],[Total usage(Min)]]<= AVERAGE(U:U)*0.9,"Low risk",TRUE,"Medium risk"),"N/A")} -> High risk | Z4: {=IFERROR(_xlfn.IFS(Table1[[#This Row],[Total charges]]>=AVERAGE(V:V)*1.1,"High risk",Table1[[#This Row],[Total charges]]<=AVERAGE(V:V)*0.9,"Low risk",TRUE,"Medium risk"),"N/A")} -> High risk | AA4: =IF(AND(Table1[[#This Row],[International plan]]="Yes",Table1[[#This Row],[Total intl minutes]]>0),"Paying & Using",IF(AND(Table1[[#This Row],[International plan]]="Yes",Table1[[#This Row],[Total intl minutes]]=0),"Paying but not using",IF(AND(Table1[[#This Row],[International plan]]="No",Table1[[#This Row],[Total intl minutes]]>0),"Unplanned usage","Inactive"))) -> Unplanned usage | AB4: =IF(AND(Table1[[#This Row],[Voice mail plan]]="Yes",Table1[[#This Row],[Number vmail messages]]>0),"Active user",IF(AND(Table1[[#This Row],[Voice mail plan]]="Yes",Table1[[#This Row],[Number vmail messages]]=0),"Unused",IF(AND(Table1[[#This Row],[Voice mail plan]]="No",Table1[[#This Row],[Number vmail messages]]>0),"Unsubscribed usage","Inactive"))) -> Inactive | AC4: {=_xlfn.IFS( AND(Table1[[#This Row],[Customer service risk level]]="High risk", Table1[[#This Row],[Intl usage behaviour]]="Unplanned Usage"),"High Risk", OR(Table1[[#This Row],[Customer service risk level]]="Medium risk", Table1[[#This Row],[Charges risk level]]="High risk "),"Medium Risk", TRUE,"Low Risk" )} -> High Risk
A5: SC | B5: 111 | C5: 415 | D5: No | E5: No | F5: 0 | G5: 110.4 | H5: 103 | I5: 18.77 | J5: 137.3 | K5: 102 | L5: 11.67 | M5: 189.6 | N5: 105 | O5: 8.53 | P5: 7.7 | Q5: 6 | R5: 2.08 | S5: 2 | T5: FALSE | U5: =IFERROR(SUM(Table1[[#This Row],[Total day minutes]],Table1[[#This Row],[Total eve minutes]],Table1[[#This Row],[Total night minutes]],Table1[[#This Row],[Total intl minutes]]),0) -> 445 | V5: =SUM(Table1[[#This Row],[Total intl charge]],Table1[[#This Row],[Total night charge]],Table1[[#This Row],[Total eve charge]],Table1[[#This Row],[Total day charge]]) -> 41.05 | W5: =SUM(Table1[[#This Row],[Total intl calls]],Table1[[#This Row],[Total night calls]],Table1[[#This Row],[Total eve calls]],Table1[[#This Row],[Total day calls]]) -> 316 | X5: {=_xlfn.IFS(Table1[[#This Row],[Customer service calls]]>=4,"High risk",Table1[[#This Row],[Customer service calls]]>=2,"Medium risk",TRUE,"Low risk")} -> Medium risk | Y5: {=IFERROR(_xlfn.IFS(Table1[[#This Row],[Total usage(Min)]]>=AVERAGE(U:U)*1.1,"High risk",Table1[[#This Row],[Total usage(Min)]]<= AVERAGE(U:U)*0.9,"Low risk",TRUE,"Medium risk"),"N/A")} -> Low risk | Z5: {=IFERROR(_xlfn.IFS(Table1[[#This Row],[Total charges]]>=AVERAGE(V:V)*1.1,"High risk",Table1[[#This Row],[Total charges]]<=AVERAGE(V:V)*0.9,"Low risk",TRUE,"Medium risk"),"N/A")} -> Low risk | AA5: =IF(AND(Table1[[#This Row],[International plan]]="Yes",Table1[[#This Row],[Total intl minutes]]>0),"Paying & Using",IF(AND(Table1[[#This Row],[International plan]]="Yes",Table1[[#This Row],[Total intl minutes]]=0),"Paying but not using",IF(AND(Table1[[#This Row],[International plan]]="No",Table1[[#This Row],[Total intl minutes]]>0),"Unplanned usage","Inactive"))) -> Unplanned usage | AB5: =IF(AND(Table1[[#This Row],[Voice mail plan]]="Yes",Table1[[#This Row],[Number vmail messages]]>0),"Active user",IF(AND(Table1[[#This Row],[Voice mail plan]]="Yes",Table1[[#This Row],[Number vmail messages]]=0),"Unused",IF(AND(Table1[[#This Row],[Voice mail plan]]="No",Table1[[#This Row],[Number vmail messages]]>0),"Unsubscribed usage","Inactive"))) -> Inactive | AC5: {=_xlfn.IFS( AND(Table1[[#This Row],[Customer service risk level]]="High risk", Table1[[#This Row],[Intl usage behaviour]]="Unplanned Usage"),"High Risk", OR(Table1[[#This Row],[Customer service risk level]]="Medium risk", Table1[[#This Row],[Charges risk level]]="High risk "),"Medium Risk", TRUE,"Low Risk" )} -> Medium Risk
A6: HI | B6: 49 | C6: 510 | D6: No | E6: No | F6: 0 | G6: 119.3 | H6: 117 | I6: 20.28 | J6: 215.1 | K6: 109 | L6: 18.28 | M6: 178.7 | N6: 90 | O6: 8.04 | P6: 11.1 | Q6: 1 | R6: 3 | S6: 1 | T6: FALSE | U6: =IFERROR(SUM(Table1[[#This Row],[Total day minutes]],Table1[[#This Row],[Total eve minutes]],Table1[[#This Row],[Total night minutes]],Table1[[#This Row],[Total intl minutes]]),0) -> 524.2 | V6: =SUM(Table1[[#This Row],[Total intl charge]],Table1[[#This Row],[Total night charge]],Table1[[#This Row],[Total eve charge]],Table1[[#This Row],[Total day charge]]) -> 49.6 | W6: =SUM(Table1[[#This Row],[Total intl calls]],Table1[[#This Row],[Total night calls]],Table1[[#This Row],[Total eve calls]],Table1[[#This Row],[Total day calls]]) -> 317 | X6: {=_xlfn.IFS(Table1[[#This Row],[Customer service calls]]>=4,"High risk",Table1[[#This Row],[Customer service calls]]>=2,"Medium risk",TRUE,"Low risk")} -> Low risk | Y6: {=IFERROR(_xlfn.IFS(Table1[[#This Row],[Total usage(Min)]]>=AVERAGE(U:U)*1.1,"High risk",Table1[[#This Row],[Total usage(Min)]]<= AVERAGE(U:U)*0.9,"Low risk",TRUE,"Medium risk"),"N/A")} -> Low risk | Z6: {=IFERROR(_xlfn.IFS(Table1[[#This Row],[Total charges]]>=AVERAGE(V:V)*1.1,"High risk",Table1[[#This Row],[Total charges]]<=AVERAGE(V:V)*0.9,"Low risk",TRUE,"Medium risk"),"N/A")} -> Low risk | AA6: =IF(AND(Table1[[#This Row],[International plan]]="Yes",Table1[[#This Row],[Total intl minutes]]>0),"Paying & Using",IF(AND(Table1[[#This Row],[International plan]]="Yes",Table1[[#This Row],[Total intl minutes]]=0),"Paying but not using",IF(AND(Table1[[#This Row],[International plan]]="No",Table1[[#This Row],[Total intl minutes]]>0),"Unplanned usage","Inactive"))) -> Unplanned usage | AB6: =IF(AND(Table1[[#This Row],[Voice mail plan]]="Yes",Table1[[#This Row],[Number vmail messages]]>0),"Active user",IF(AND(Table1[[#This Row],[Voice mail plan]]="Yes",Table1[[#This Row],[Number vmail messages]]=0),"Unused",IF(AND(Table1[[#This Row],[Voice mail plan]]="No",Table1[[#This Row],[Number vmail messages]]>0),"Unsubscribed usage","Inactive"))) -> Inactive | AC6: {=_xlfn.IFS( AND(Table1[[#This Row],[Customer service risk level]]="High risk", Table1[[#This Row],[Intl usage behaviour]]="Unplanned Usage"),"High Risk", OR(Table1[[#This Row],[Customer service risk level]]="Medium risk", Table1[[#This Row],[Charges risk level]]="High risk "),"Medium Risk", TRUE,"Low Risk" )} -> Low Risk
A7: AK | B7: 36 | C7: 408 | D7: No | E7: Yes | F7: 30 | G7: 146.3 | H7: 128 | I7: 24.87 | J7: 162.5 | K7: 80 | L7: 13.81 | M7: 129.3 | N7: 109 | O7: 5.82 | P7: 14.5 | Q7: 6 | R7: 3.92 | S7: 0 | T7: FALSE | U7: =IFERROR(SUM(Table1[[#This Row],[Total day minutes]],Table1[[#This Row],[Total eve minutes]],Table1[[#This Row],[Total night minutes]],Table1[[#This Row],[Total intl minutes]]),0) -> 452.6 | V7: =SUM(Table1[[#This Row],[Total intl charge]],Table1[[#This Row],[Total night charge]],Table1[[#This Row],[Total eve charge]],Table1[[#This Row],[Total day charge]]) -> 48.42 | W7: =SUM(Table1[[#This Row],[Total intl calls]],Table1[[#This Row],[Total night calls]],Table1[[#This Row],[Total eve calls]],Table1[[#This Row],[Total day calls]]) -> 323 | X7: {=_xlfn.IFS(Table1[[#This Row],[Customer service calls]]>=4,"High risk",Table1[[#This Row],[Customer service calls]]>=2,"Medium risk",TRUE,"Low risk")} -> Low risk | Y7: {=IFERROR(_xlfn.IFS(Table1[[#This Row],[Total usage(Min)]]>=AVERAGE(U:U)*1.1,"High risk",Table1[[#This Row],[Total usage(Min)]]<= AVERAGE(U:U)*0.9,"Low risk",TRUE,"Medium risk"),"N/A")} -> Low risk | Z7: {=IFERROR(_xlfn.IFS(Table1[[#This Row],[Total charges]]>=AVERAGE(V:V)*1.1,"High risk",Table1[[#This Row],[Total charges]]<=AVERAGE(V:V)*0.9,"Low risk",TRUE,"Medium risk"),"N/A")} -> Low risk | AA7: =IF(AND(Table1[[#This Row],[International plan]]="Yes",Table1[[#This Row],[Total intl minutes]]>0),"Paying & Using",IF(AND(Table1[[#This Row],[International plan]]="Yes",Table1[[#This Row],[Total intl minutes]]=0),"Paying but not using",IF(AND(Table1[[#This Row],[International plan]]="No",Table1[[#This Row],[Total intl minutes]]>0),"Unplanned usage","Inactive"))) -> Unplanned usage | AB7: =IF(AND(Table1[[#This Row],[Voice mail plan]]="Yes",Table1[[#This Row],[Number vmail messages]]>0),"Active user",IF(AND(Table1[[#This Row],[Voice mail plan]]="Yes",Table1[[#This Row],[Number vmail messages]]=0),"Unused",IF(AND(Table1[[#This Row],[Voice mail plan]]="No",Table1[[#This Row],[Number vmail messages]]>0),"Unsubscribed usage","Inactive"))) -> Active user | AC7: {=_xlfn.IFS( AND(Table1[[#This Row],[Customer service risk level]]="High risk", Table1[[#This Row],[Intl usage behaviour]]="Unplanned Usage"),"High Risk", OR(Table1[[#This Row],[Customer service risk level]]="Medium risk", Table1[[#This Row],[Charges risk level]]="High risk "),"Medium Risk", TRUE,"Low Risk" )} -> Low Risk
A8: MI | B8: 65 | C8: 415 | D8: No | E8: No | F8: 0 | G8: 211.3 | H8: 120 | I8: 35.92 | J8: 162.6 | K8: 122 | L8: 13.82 | M8: 134.7 | N8: 118 | O8: 6.06 | P8: 13.2 | Q8: 5 | R8: 3.56 | S8: 3 | T8: FALSE | U8: =IFERROR(SUM(Table1[[#This Row],[Total day minutes]],Table1[[#This Row],[Total eve minutes]],Table1[[#This Row],[Total night minutes]],Table1[[#This Row],[Total intl minutes]]),0) -> 521.8 | V8: =SUM(Table1[[#This Row],[Total intl charge]],Table1[[#This Row],[Total night charge]],Table1[[#This Row],[Total eve charge]],Table1[[#This Row],[Total day charge]]) -> 59.36 | W8: =SUM(Table1[[#This Row],[Total intl calls]],Table1[[#This Row],[Total night calls]],Table1[[#This Row],[Total eve calls]],Table1[[#This Row],[Total day calls]]) -> 365 | X8: {=_xlfn.IFS(Table1[[#This Row],[Customer service calls]]>=4,"High risk",Table1[[#This Row],[Customer service calls]]>=2,"Medium risk",TRUE,"Low risk")} -> Medium risk | Y8: {=IFERROR(_xlfn.IFS(Table1[[#This Row],[Total usage(Min)]]>=AVERAGE(U:U)*1.1,"High risk",Table1[[#This Row],[Total usage(Min)]]<= AVERAGE(U:U)*0.9,"Low risk",TRUE,"Medium risk"),"N/A")} -> Low risk | Z8: {=IFERROR(_xlfn.IFS(Table1[[#This Row],[Total charges]]>=AVERAGE(V:V)*1.1,"High risk",Table1[[#This Row],[Total charges]]<=AVERAGE(V:V)*0.9,"Low risk",TRUE,"Medium risk"),"N/A")} -> Medium risk | AA8: =IF(AND(Table1[[#This Row],[International plan]]="Yes",Table1[[#This Row],[Total intl minutes]]>0),"Paying & Using",IF(AND(Table1[[#This Row],[International plan]]="Yes",Table1[[#This Row],[Total intl minutes]]=0),"Paying but not using",IF(AND(Table1[[#This Row],[International plan]]="No",Table1[[#This Row],[Total intl minutes]]>0),"Unplanned usage","Inactive"))) -> Unplanned usage | AB8: =IF(AND(Table1[[#This Row],[Voice mail plan]]="Yes",Table1[[#This Row],[Number vmail messages]]>0),"Active user",IF(AND(Table1[[#This Row],[Voice mail plan]]="Yes",Table1[[#This Row],[Number vmail messages]]=0),"Unused",IF(AND(Table1[[#This Row],[Voice mail plan]]="No",Table1[[#This Row],[Number vmail messages]]>0),"Unsubscribed usage","Inactive"))) -> Inactive | AC8: {=_xlfn.IFS( AND(Table1[[#This Row],[Customer service risk level]]="High risk", Table1[[#This Row],[Intl usage behaviour]]="Unplanned Usage"),"High Risk", OR(Table1[[#This Row],[Customer service risk level]]="Medium risk", Table1[[#This Row],[Charges risk level]]="High risk "),"Medium Risk", TRUE,"Low Risk" )} -> Medium Risk
A9: ID | B9: 119 | C9: 415 | D9: No | E9: No | F9: 0 | G9: 159.1 | H9: 114 | I9: 27.05 | J9: 231.3 | K9: 117 | L9: 19.66 | M9: 143.2 | N9: 91 | O9: 6.44 | P9: 8.8 | Q9: 3 | R9: 2.38 | S9: 5 | T9: TRUE | U9: =IFERROR(SUM(Table1[[#This Row],[Total day minutes]],Table1[[#This Row],[Total eve minutes]],Table1[[#This Row],[Total night minutes]],Table1[[#This Row],[Total intl minutes]]),0) -> 542.4 | V9: =SUM(Table1[[#This Row],[Total intl charge]],Table1[[#This Row],[Total night charge]],Table1[[#This Row],[Total eve charge]],Table1[[#This Row],[Total day charge]]) -> 55.53 | W9: =SUM(Table1[[#This Row],[Total intl calls]],Table1[[#This Row],[Total night calls]],Table1[[#This Row],[Total eve calls]],Table1[[#This Row],[Total day calls]]) -> 325 | X9: {=_xlfn.IFS(Table1[[#This Row],[Customer service calls]]>=4,"High risk",Table1[[#This Row],[Customer service calls]]>=2,"Medium risk",TRUE,"Low risk")} -> High risk | Y9: {=IFERROR(_xlfn.IFS(Table1[[#This Row],[Total usage(Min)]]>=AVERAGE(U:U)*1.1,"High risk",Table1[[#This Row],[Total usage(Min)]]<= AVERAGE(U:U)*0.9,"Low risk",TRUE,"Medium risk"),"N/A")} -> Medium risk | Z9: {=IFERROR(_xlfn.IFS(Table1[[#This Row],[Total charges]]>=AVERAGE(V:V)*1.1,"High risk",Table1[[#This Row],[Total charges]]<=AVERAGE(V:V)*0.9,"Low risk",TRUE,"Medium risk"),"N/A")} -> Medium risk | AA9: =IF(AND(Table1[[#This Row],[International plan]]="Yes",Table1[[#This Row],[Total intl minutes]]>0),"Paying & Using",IF(AND(Table1[[#This Row],[International plan]]="Yes",Table1[[#This Row],[Total intl minutes]]=0),"Paying but not using",IF(AND(Table1[[#This Row],[International plan]]="No",Table1[[#This Row],[Total intl minutes]]>0),"Unplanned usage","Inactive"))) -> Unplanned usage | AB9: =IF(AND(Table1[[#This Row],[Voice mail plan]]="Yes",Table1[[#This Row],[Number vmail messages]]>0),"Active user",IF(AND(Table1[[#This Row],[Voice mail plan]]="Yes",Table1[[#This Row],[Number vmail messages]]=0),"Unused",IF(AND(Table1[[#This Row],[Voice mail plan]]="No",Table1[[#This Row],[Number vmail messages]]>0),"Unsubscribed usage","Inactive"))) -> Inactive | AC9: {=_xlfn.IFS( AND(Table1[[#This Row],[Customer service risk level]]="High risk", Table1[[#This Row],[Intl usage behaviour]]="Unplanned Usage"),"High Risk", OR(Table1[[#This Row],[Customer service risk level]]="Medium risk", Table1[[#This Row],[Charges risk level]]="High risk "),"Medium Risk", TRUE,"Low Risk" )} -> High Risk
A10: VA | B10: 10 | C10: 408 | D10: No | E10: No | F10: 0 | G10: 186.1 | H10: 112 | I10: 31.64 | J10: 190.2 | K10: 66 | L10: 16.17 | M10: 282.8 | N10: 57 | O10: 12.73 | P10: 11.4 | Q10: 6 | R10: 3.08 | S10: 2 | T10: FALSE | U10: =IFERROR(SUM(Table1[[#This Row],[Total day minutes]],Table1[[#This Row],[Total eve minutes]],Table1[[#This Row],[Total night minutes]],Table1[[#This Row],[Total intl minutes]]),0) -> 670.5 | V10: =SUM(Table1[[#This Row],[Total intl charge]],Table1[[#This Row],[Total night charge]],Table1[[#This Row],[Total eve charge]],Table1[[#This Row],[Total day charge]]) -> 63.62 | W10: =SUM(Table1[[#This Row],[Total intl calls]],Table1[[#This Row],[Total night calls]],Table1[[#This Row],[Total eve calls]],Table1[[#This Row],[Total day calls]]) -> 241 | X10: {=_xlfn.IFS(Table1[[#This Row],[Customer service calls]]>=4,"High risk",Table1[[#This Row],[Customer service calls]]>=2,"Medium risk",TRUE,"Low risk")} -> Medium risk | Y10: {=IFERROR(_xlfn.IFS(Table1[[#This Row],[Total usage(Min)]]>=AVERAGE(U:U)*1.1,"High risk",Table1[[#This Row],[Total usage(Min)]]<= AVERAGE(U:U)*0.9,"Low risk",TRUE,"Medium risk"),"N/A")} -> High risk | Z10: {=IFERROR(_xlfn.IFS(Table1[[#This Row],[Total charges]]>=AVERAGE(V:V)*1.1,"High risk",Table1[[#This Row],[Total charges]]<=AVERAGE(V:V)*0.9,"Low risk",TRUE,"Medium risk"),"N/A")} -> Medium risk | AA10: =IF(AND(Table1[[#This Row],[International plan]]="Yes",Table1[[#This Row],[Total intl minutes]]>0),"Paying & Using",IF(AND(Table1[[#This Row],[International plan]]="Yes",Table1[[#This Row],[Total intl minutes]]=0),"Paying but not using",IF(AND(Table1[[#This Row],[International plan]]="No",Table1[[#This Row],[Total intl minutes]]>0),"Unplanned usage","Inactive"))) -> Unplanned usage | AB10: =IF(AND(Table1[[#This Row],[Voice mail plan]]="Yes",Table1[[#This Row],[Number vmail messages]]>0),"Active user",IF(AND(Table1[[#This Row],[Voice mail plan]]="Yes",Table1[[#This Row],[Number vmail messages]]=0),"Unused",IF(AND(Table1[[#This Row],[Voice mail plan]]="No",Table1[[#This Row],[Number vmail messages]]>0),"Unsubscribed usage","Inactive"))) -> Inactive | AC10: {=_xlfn.IFS( AND(Table1[[#This Row],[Customer service risk level]]="High risk", Table1[[#This Row],[Intl usage behaviour]]="Unplanned Usage"),"High Risk", OR(Table1[[#This Row],[Customer service risk level]]="Medium risk", Table1[[#This Row],[Charges risk level]]="High risk "),"Medium Risk", TRUE,"Low Risk" )} -> Medium Risk
A11: WI | B11: 68 | C11: 415 | D11: No | E11: No | F11: 0 | G11: 148.8 | H11: 70 | I11: 25.3 | J11: 246.5 | K11: 164 | L11: 20.95 | M11: 129.8 | N11: 103 | O11: 5.84 | P11: 12.1 | Q11: 3 | R11: 3.27 | S11: 3 | T11: FALSE | U11: =IFERROR(SUM(Table1[[#This Row],[Total day minutes]],Table1[[#This Row],[Total eve minutes]],Table1[[#This Row],[Total night minutes]],Table1[[#This Row],[Total intl minutes]]),0) -> 537.2 | V11: =SUM(Table1[[#This Row],[Total intl charge]],Table1[[#This Row],[Total night charge]],Table1[[#This Row],[Total eve charge]],Table1[[#This Row],[Total day charge]]) -> 55.36 | W11: =SUM(Table1[[#This Row],[Total intl calls]],Table1[[#This Row],[Total night calls]],Table1[[#This Row],[Total eve calls]],Table1[[#This Row],[Total day calls]]) -> 340 | X11: {=_xlfn.IFS(Table1[[#This Row],[Customer service calls]]>=4,"High risk",Table1[[#This Row],[Customer service calls]]>=2,"Medium risk",TRUE,"Low risk")} -> Medium risk | Y11: {=IFERROR(_xlfn.IFS(Table1[[#This Row],[Total usage(Min)]]>=AVERAGE(U:U)*1.1,"High risk",Table1[[#This Row],[Total usage(Min)]]<= AVERAGE(U:U)*0.9,"Low risk",TRUE,"Medium risk"),"N/A")} -> Medium risk | Z11: {=IFERROR(_xlfn.IFS(Table1[[#This Row],[Total charges]]>=AVERAGE(V:V)*1.1,"High risk",Table1[[#This Row],[Total charges]]<=AVERAGE(V:V)*0.9,"Low risk",TRUE,"Medium risk"),"N/A")} -> Medium risk | AA11: =IF(AND(Table1[[#This Row],[International plan]]="Yes",Table1[[#This Row],[Total intl minutes]]>0),"Paying & Using",IF(AND(Table1[[#This Row],[International plan]]="Yes",Table1[[#This Row],[Total intl minutes]]=0),"Paying but not using",IF(AND(Table1[[#This Row],[International plan]]="No",Table1[[#This Row],[Total intl minutes]]>0),"Unplanned usage","Inactive"))) -> Unplanned usage | AB11: =IF(AND(Table1[[#This Row],[Voice mail plan]]="Yes",Table1[[#This Row],[Number vmail messages]]>0),"Active user",IF(AND(Table1[[#This Row],[Voice mail plan]]="Yes",Table1[[#This Row],[Number vmail messages]]=0),"Unused",IF(AND(Table1[[#This Row],[Voice mail plan]]="No",Table1[[#This Row],[Number vmail messages]]>0),"Unsubscribed usage","Inactive"))) -> Inactive | AC11: {=_xlfn.IFS( AND(Table1[[#This Row],[Customer service risk level]]="High risk", Table1[[#This Row],[Intl usage behaviour]]="Unplanned Usage"),"High Risk", OR(Table1[[#This Row],[Customer service risk level]]="Medium risk", Table1[[#This Row],[Charges risk level]]="High risk "),"Medium Risk", TRUE,"Low Risk" )} -> Medium Risk
A12: MN | B12: 74 | C12: 510 | D12: No | E12: Yes | F12: 33 | G12: 193.7 | H12: 91 | I12: 32.93 | J12: 246.1 | K12: 96 | L12: 20.92 | M12: 138 | N12: 92 | O12: 6.21 | P12: 14.6 | Q12: 3 | R12: 3.94 | S12: 2 | T12: FALSE | U12: =IFERROR(SUM(Table1[[#This Row],[Total day minutes]],Table1[[#This Row],[Total eve minutes]],Table1[[#This Row],[Total night minutes]],Table1[[#This Row],[Total intl minutes]]),0) -> 592.4 | V12: =SUM(Table1[[#This Row],[Total intl charge]],Table1[[#This Row],[Total night charge]],Table1[[#This Row],[Total eve charge]],Table1[[#This Row],[Total day charge]]) -> 64 | W12: =SUM(Table1[[#This Row],[Total intl calls]],Table1[[#This Row],[Total night calls]],Table1[[#This Row],[Total eve calls]],Table1[[#This Row],[Total day calls]]) -> 282 | X12: {=_xlfn.IFS(Table1[[#This Row],[Customer service calls]]>=4,"High risk",Table1[[#This Row],[Customer service calls]]>=2,"Medium risk",TRUE,"Low risk")} -> Medium risk | Y12: {=IFERROR(_xlfn.IFS(Table1[[#This Row],[Total usage(Min)]]>=AVERAGE(U:U)*1.1,"High risk",Table1[[#This Row],[Total usage(Min)]]<= AVERAGE(U:U)*0.9,"Low risk",TRUE,"Medium risk"),"N/A")} -> Medium risk | Z12: {=IFERROR(_xlfn.IFS(Table1[[#This Row],[Total charges]]>=AVERAGE(V:V)*1.1,"High risk",Table1[[#This Row],[Total charges]]<=AVERAGE(V:V)*0.9,"Low risk",TRUE,"Medium risk"),"N/A")} -> Medium risk | AA12: =IF(AND(Table1[[#This Row],[International plan]]="Yes",Table1[[#This Row],[Total intl minutes]]>0),"Paying & Using",IF(AND(Table1[[#This Row],[International plan]]="Yes",Table1[[#This Row],[Total intl minutes]]=0),"Paying but not using",IF(AND(Table1[[#This Row],[International plan]]="No",Table1[[#This Row],[Total intl minutes]]>0),"Unplanned usage","Inactive"))) -> Unplanned usage | AB12: =IF(AND(Table1[[#This Row],[Voice mail plan]]="Yes",Table1[[#This Row],[Number vmail messages]]>0),"Active user",IF(AND(Table1[[#This Row],[Voice mail plan]]="Yes",Table1[[#This Row],[Number vmail messages]]=0),"Unused",IF(AND(Table1[[#This Row],[Voice mail plan]]="No",Table1[[#This Row],[Number vmail messages]]>0),"Unsubscribed usage","Inactive"))) -> Active user | AC12: {=_xlfn.IFS( AND(Table1[[#This Row],[Customer service risk level]]="High risk", Table1[[#This Row],[Intl usage behaviour]]="Unplanned Usage"),"High Risk", OR(Table1[[#This Row],[Customer service risk level]]="Medium risk", Table1[[#This Row],[Charges risk level]]="High risk "),"Medium Risk", TRUE,"Low Risk" )} -> Medium Risk
A13: HI | B13: 85 | C13: 415 | D13: No | E13: No | F13: 0 | G13: 235.8 | H13: 109 | I13: 40.09 | J13: 157.2 | K13: 94 | L13: 13.36 | M13: 188.2 | N13: 99 | O13: 8.47 | P13: 12 | Q13: 3 | R13: 3.24 | S13: 0 | T13: FALSE | U13: =IFERROR(SUM(Table1[[#This Row],[Total day minutes]],Table1[[#This Row],[Total eve minutes]],Table1[[#This Row],[Total night minutes]],Table1[[#This Row],[Total intl minutes]]),0) -> 593.2 | V13: =SUM(Table1[[#This Row],[Total intl charge]],Table1[[#This Row],[Total night charge]],Table1[[#This Row],[Total eve charge]],Table1[[#This Row],[Total day charge]]) -> 65.16 | W13: =SUM(Table1[[#This Row],[Total intl calls]],Table1[[#This Row],[Total night calls]],Table1[[#This Row],[Total eve calls]],Table1[[#This Row],[Total day calls]]) -> 305 | X13: {=_xlfn.IFS(Table1[[#This Row],[Customer service calls]]>=4,"High risk",Table1[[#This Row],[Customer service calls]]>=2,"Medium risk",TRUE,"Low risk")} -> Low risk | Y13: {=IFERROR(_xlfn.IFS(Table1[[#This Row],[Total usage(Min)]]>=AVERAGE(U:U)*1.1,"High risk",Table1[[#This Row],[Total usage(Min)]]<= AVERAGE(U:U)*0.9,"Low risk",TRUE,"Medium risk"),"N/A")} -> Medium risk | Z13: {=IFERROR(_xlfn.IFS(Table1[[#This Row],[Total charges]]>=AVERAGE(V:V)*1.1,"High risk",Table1[[#This Row],[Total charges]]<=AVERAGE(V:V)*0.9,"Low risk",TRUE,"Medium risk"),"N/A")} -> Medium risk | AA13: =IF(AND(Table1[[#This Row],[International plan]]="Yes",Table1[[#This Row],[Total intl minutes]]>0),"Paying & Using",IF(AND(Table1[[#This Row],[International plan]]="Yes",Table1[[#This Row],[Total intl minutes]]=0),"Paying but not using",IF(AND(Table1[[#This Row],[International plan]]="No",Table1[[#This Row],[Total intl minutes]]>0),"Unplanned usage","Inactive"))) -> Unplanned usage | AB13: =IF(AND(Table1[[#This Row],[Voice mail plan]]="Yes",Table1[[#This Row],[Number vmail messages]]>0),"Active user",IF(AND(Table1[[#This Row],[Voice mail plan]]="Yes",Table1[[#This Row],[Number vmail messages]]=0),"Unused",IF(AND(Table1[[#This Row],[Voice mail plan]]="No",Table1[[#This Row],[Number vmail messages]]>0),"Unsubscribed usage","Inactive"))) -> Inactive | AC13: {=_xlfn.IFS( AND(Table1[[#This Row],[Customer service risk level]]="High risk", Table1[[#This Row],[Intl usage behaviour]]="Unplanned Usage"),"High Risk", OR(Table1[[#This Row],[Customer service risk level]]="Medium risk", Table1[[#This Row],[Charges risk level]]="High risk "),"Medium Risk", TRUE,"Low Risk" )} -> Low Risk
... A668: CT | B668: 184 | C668: 510 | D668: Yes | E668: No | F668: 0 | G668: 213.8 | H668: 105 | I668: 36.35 | J668: 159.6 | K668: 84 | L668: 13.57 | M668: 139.2 | N668: 137 | O668: 6.26 | P668: 5 | Q668: 10 | R668: 1.35 | S668: 2 | T668: FALSE | U668: =IFERROR(SUM(Table1[[#This Row],[Total day minutes]],Table1[[#This Row],[Total eve minutes]],Table1[[#This Row],[Total night minutes]],Table1[[#This Row],[Total intl minutes]]),0) -> 517.6 | V668: =SUM(Table1[[#This Row],[Total intl charge]],Table1[[#This Row],[Total night charge]],Table1[[#This Row],[Total eve charge]],Table1[[#This Row],[Total day charge]]) -> 57.53 | W668: =SUM(Table1[[#This Row],[Total intl calls]],Table1[[#This Row],[Total night calls]],Table1[[#This Row],[Total eve calls]],Table1[[#This Row],[Total day calls]]) -> 336 | X668: {=_xlfn.IFS(Table1[[#This Row],[Customer service calls]]>=4,"High risk",Table1[[#This Row],[Customer service calls]]>=2,"Medium risk",TRUE,"Low risk")} -> Medium risk | Y668: {=IFERROR(_xlfn.IFS(Table1[[#This Row],[Total usage(Min)]]>=AVERAGE(U:U)*1.1,"High risk",Table1[[#This Row],[Total usage(Min)]]<= AVERAGE(U:U)*0.9,"Low risk",TRUE,"Medium risk"),"N/A")} -> Low risk | Z668: {=IFERROR(_xlfn.IFS(Table1[[#This Row],[Total charges]]>=AVERAGE(V:V)*1.1,"High risk",Table1[[#This Row],[Total charges]]<=AVERAGE(V:V)*0.9,"Low risk",TRUE,"Medium risk"),"N/A")} -> Medium risk | AA668: =IF(AND(Table1[[#This Row],[International plan]]="Yes",Table1[[#This Row],[Total intl minutes]]>0),"Paying & Using",IF(AND(Table1[[#This Row],[International plan]]="Yes",Table1[[#This Row],[Total intl minutes]]=0),"Paying but not using",IF(AND(Table1[[#This Row],[International plan]]="No",Table1[[#This Row],[Total intl minutes]]>0),"Unplanned usage","Inactive"))) -> Paying & Using | AB668: =IF(AND(Table1[[#This Row],[Voice mail plan]]="Yes",Table1[[#This Row],[Number vmail messages]]>0),"Active user",IF(AND(Table1[[#This Row],[Voice mail plan]]="Yes",Table1[[#This Row],[Number vmail messages]]=0),"Unused",IF(AND(Table1[[#This Row],[Voice mail plan]]="No",Table1[[#This Row],[Number vmail messages]]>0),"Unsubscribed usage","Inactive"))) -> Inactive | AC668: {=_xlfn.IFS( AND(Table1[[#This Row],[Customer service risk level]]="High risk", Table1[[#This Row],[Intl usage behaviour]]="Unplanned Usage"),"High Risk", OR(Table1[[#This Row],[Customer service risk level]]="Medium risk", Table1[[#This Row],[Charges risk level]]="High risk "),"Medium Risk", TRUE,"Low Risk" )} -> Medium Risk

Sheet Dynamic Array Analysis 1
A1: States | C1: High risk Customers | F1: Churned customers | H1: High risk & Churned
A2: {=_xlfn._xlws.SORT(_xlfn.UNIQUE('churn-bigml-20'!A:A))} -> AK | C2: {=_xlfn._xlws.FILTER('churn-bigml-20'!A:A,'churn-bigml-20'!AC:AC="High risk")} -> IN | F2: {=_xlfn._xlws.FILTER('churn-bigml-20'!A:A,'churn-bigml-20'!T:T=TRUE)} -> IN | H2: {=_xlfn._xlws.FILTER('churn-bigml-20'!A:A,(ISNUMBER(SEARCH("High risk",'churn-bigml-20'!AC:AC)))*('churn-bigml-20'!T:T=TRUE))} -> IN
A3: AL | C3: NY | F3: NY | H3: NY
A4: AR | C4: ID | F4: ID | H4: ID
A5: AZ | C5: MN | F5: LA | H5: MN
A6: CA | C6: AZ | F6: ID | H6: CT
A7: CO | C7: FL | F7: TX | H7: IN
A8: CT | C8: CT | F8: MN | H8: OK
A9: DC | C9: IN | F9: KS | H9: CA
A10: DE | C10: ID | F10: SD | H10: UT
A11: FL | C11: LA | F11: OK | H11: NY
A12: GA | C12: OK | F12: CT | H12: MI
A13: HI | C13: CA | F13: FL | H13: MT
A14: IA | C14: WI | F14: RI | H14: MS
... A24: MI | C24: AZ | F24: OK | H24: MT
A25: MN | C25: MT | F25: NV
A26: MO | C26: MS | F26: CA
A27: MS | C27: SC | F27: MT
A28: MT | C28: AZ | F28: WV
A29: NC | C29: WY | F29: UT
A30: ND | C30: MO | F30: WI
A31: NE | C31: DC | F31: VA
A32: NH | C32: OH | F32: SC
A33: NJ | C33: WA | F33: MA
A34: NM | C34: KY | F34: NJ
A35: NV | C35: CT | F35: DE
A36: NY | C36: IA | F36: NY
... A52: WV | C52: OR | F52: NJ
A53: WY | F53: WA
A54: 0 | F54: NC
F55: TX
F56: SD
F57: WA
F58: HI
F59: ND
F60: KY
F61: KS
F62: CA
F63: NM
F64: NE
...

Sheet Analysis
A1: Churn risk segmentation | J1: Churn distribution
A2: Count of Account length | B2: Column Labels | H2: Average of Customer service calls | J2: Row Labels | K2: Count of Account length
A3: Row Labels | B3: FALSE | C3: TRUE | D3: Grand Total | F3: Churn rate | H3: 1.5637181 | J3: FALSE | K3: 572
A4: High Risk | B4: 28 | C4: 23 | D4: 51 | E4: High Risk | F4: =C4/D4 -> 0.45098039 | J4: TRUE | K4: 95
A5: Low Risk | B5: 344 | C5: 40 | D5: 384 | E5: Low Risk | F5: =C5/D5 -> 0.10416667 | H5: Average of Total charges | J5: Grand Total | K5: 667
A6: Medium Risk | B6: 200 | C6: 32 | D6: 232 | E6: Medium Risk | F6: =C6/D6 -> 0.13793103 | H6: 59.797886
A7: Grand Total | B7: 572 | C7: 95 | D7: 667 | E7: Total churn rate | F7: =C7/D7 -> 0.14242879 | J7: Risk distribution
J8: Row Labels | K8: Count of Account length
A9: Customer service calls distribution | J9: Low Risk | K9: 384
A10: Count of Account length | B10: Column Labels | J10: Medium Risk | K10: 232
A11: Row Labels | B11: TRUE | C11: Grand Total | F11: Retention oppurtunity (high risk) | J11: High Risk | K11: 51
A12: 2 | B12: 25 | C12: 25 | F12: Drivers | G12: customers | H12: % | J12: Grand Total | K12: 667
A13: 1 | B13: 23 | C13: 23 | F13: Unplanned intl usage | G13: =COUNTIF('churn-bigml-20'!AA:AA,"Unplanned usage") -> 611 | H13: =Table4[[#This Row],[customers]]/SUM(Table4[customers]) -> 0.41283784
A14: 0 | B14: 13 | C14: 13 | F14: Inactive voicemail usage | G14: =COUNTIF('churn-bigml-20'!AB:AB,"Inactive") -> 478 | H14: =Table4[[#This Row],[customers]]/SUM(Table4[customers]) -> 0.32297297
A15: 4 | B15: 12 | C15: 12 | F15: Charges | G15: =COUNTIF('churn-bigml-20'!Z:Z,"High risk") -> 176 | H15: =Table4[[#This Row],[customers]]/SUM(Table4[customers]) -> 0.11891892 | J15: Customer service calls vs churn
A16: 5 | B16: 11 | C16: 11 | F16: Customer Usage | G16: =COUNTIF('churn-bigml-20'!Y:Y,"High risk") -> 158 | H16: =Table4[[#This Row],[customers]]/SUM(Table4[customers]) -> 0.10675676 | J16: Count of Account length | K16: Column Labels
A17: 3 | B17: 7 | C17: 7 | F17: Customer service calls | G17: =COUNTIF('churn-bigml-20'!X:X,"High risk") -> 57 | H17: =Table4[[#This Row],[customers]]/SUM(Table4[customers]) -> 0.038513514 | J17: Row Labels | K17: FALSE | L17: TRUE | M17: Grand Total
A18: 6 | B18: 4 | C18: 4 | J18: High risk | K18: 0.52631579 | L18: 0.47368421 | M18: 1
A19: Grand Total | B19: 95 | C19: 95 | J19: Low risk | K19: 0.9047619 | L19: 0.095238095 | M19: 1
F20: Churn by area code | J20: Medium risk | K20: 0.86206897 | L20: 0.13793103 | M20: 1
F21: Count of Account length | G21: Column Labels | J21: Grand Total | K21: 0.85757121 | L21: 0.14242879 | M21: 1
F22: Row Labels | G22: TRUE | H22: Grand Total
A23: Charges vs churn | F23: 415 | G23: 41 | H23: 41 | J23: Customer Usage vs Churn
A24: Count of Account length | B24: Column Labels | F24: 408 | G24: 28 | H24: 28 | J24: Count of Account length | K24: Column Labels
A25: Row Labels | B25: FALSE | C25: TRUE | D25: Grand Total | F25: 510 | G25: 26 | H25: 26 | J25: Row Labels | K25: FALSE | L25: TRUE | M25: Grand Total
A26: High risk | B26: 0.68181818 | C26: 0.31818182 | D26: 1 | F26: Grand Total | G26: 95 | H26: 95 | J26: High risk | K26: 0.65189873 | L26: 0.34810127 | M26: 1
A27: Low risk | B27: 0.88297872 | C27: 0.11702128 | D27: 1 | J27: Low risk | K27: 0.88095238 | L27: 0.11904762 | M27: 1
A28: Medium risk | B28: 0.94389439 | C28: 0.056105611 | D28: 1 | F28: Churn rate | J28: Medium risk | K28: 0.94134897 | L28: 0.058651026 | M28: 1
A29: Grand Total | B29: 0.85757121 | C29: 0.14242879 | D29: 1 | F29: Row Labels | G29: Count of Account length | J29: Grand Total | K29: 0.85757121 | L29: 0.14242879 | M29: 1
F30: FALSE | G30: 0.85757121
A31: International plan vs churn | F31: TRUE | G31: 0.14242879 | J31: High risk customer segments
A32: Count of Account length | B32: Column Labels | F32: Grand Total | G32: 1 | J32: Count of Account length | K32: Column Labels
A33: Row Labels | B33: FALSE | C33: TRUE | D33: Grand Total | J33: Row Labels | K33: FALSE | L33: TRUE | M33: Grand Total
A34: Inactive | B34: 1 | C34: 0 | D34: 1 | F34: Key drivers ranking | J34: High Risk | K34: 28 | L34: 23 | M34: 51
A35: Paying & Using | B35: 0.64150943 | C35: 0.35849057 | D35: 1 | F35: Drivers | G35: Impact | J35: Low Risk | K35: 344 | L35: 40 | M35: 384
A36: Unplanned usage | B36: 0.87561375 | C36: 0.12438625 | D36: 1 | F36: Customer service | G36: =L20 -> 0.13793103 | J36: Medium Risk | K36: 200 | L36: 32 | M36: 232
A37: Grand Total | B37: 0.85757121 | C37: 0.14242879 | D37: 1 | F37: International usage | G37: =C35 -> 0.35849057 | J37: Grand Total | K37: 572 | L37: 95 | M37: 667
F38: Customer usage | G38: =L28 -> 0.058651026
A39: Voicemail plan vs churn | F39: Charges | G39: =C28 -> 0.056105611
A40: Count of Account length | B40: Column Labels | F40: Voicemail usage | G40: =C42 -> 0.16736402
...

Sheet Dashboard
